{
 "cells": [
  {
   "cell_type": "code",
   "execution_count": 20,
   "metadata": {},
   "outputs": [],
   "source": [
    "import os\n",
    "import pandas as pd\n",
    "import numpy as np\n",
    "import matplotlib.pyplot as plt"
   ]
  },
  {
   "cell_type": "code",
   "execution_count": 21,
   "metadata": {},
   "outputs": [],
   "source": [
    "import tensorflow as tf\n",
    "import keras\n",
    "from keras.preprocessing.image import ImageDataGenerator"
   ]
  },
  {
   "cell_type": "code",
   "execution_count": 22,
   "metadata": {},
   "outputs": [
    {
     "data": {
      "text/plain": [
       "39"
      ]
     },
     "execution_count": 22,
     "metadata": {},
     "output_type": "execute_result"
    }
   ],
   "source": [
    "#EDA\n",
    "\n",
    "len(os.listdir(\"datasets/New Plant Diseases Dataset(Augmented)/New Plant Diseases Dataset(Augmented)/train\"))"
   ]
  },
  {
   "cell_type": "code",
   "execution_count": 23,
   "metadata": {},
   "outputs": [],
   "source": [
    "train_data_gen = ImageDataGenerator(rescale= 1./255,zoom_range= 0.6, shear_range = 0.3, horizontal_flip = True, fill_mode='nearest')\n",
    "\n",
    "validation_data_gen = ImageDataGenerator(rescale= 1./255)"
   ]
  },
  {
   "cell_type": "code",
   "execution_count": 24,
   "metadata": {},
   "outputs": [
    {
     "name": "stdout",
     "output_type": "stream",
     "text": [
      "Found 70295 images belonging to 38 classes.\n",
      "Found 17572 images belonging to 38 classes.\n"
     ]
    }
   ],
   "source": [
    "training_set = train_data_gen.flow_from_directory(directory = \"datasets/New Plant Diseases Dataset(Augmented)/New Plant Diseases Dataset(Augmented)/train\", target_size = (256, 256), batch_size = 32)\n",
    "\n",
    "validation_set = validation_data_gen.flow_from_directory(directory = \"datasets/New Plant Diseases Dataset(Augmented)/New Plant Diseases Dataset(Augmented)/valid\", target_size = (256, 256,), batch_size = 32)\n"
   ]
  },
  {
   "cell_type": "code",
   "execution_count": 25,
   "metadata": {},
   "outputs": [
    {
     "name": "stderr",
     "output_type": "stream",
     "text": [
      "2023-02-25 14:54:03.123015: I tensorflow/core/common_runtime/pluggable_device/pluggable_device_factory.cc:305] Could not identify NUMA node of platform GPU ID 0, defaulting to 0. Your kernel may not have been built with NUMA support.\n",
      "2023-02-25 14:54:03.125059: I tensorflow/core/common_runtime/pluggable_device/pluggable_device_factory.cc:271] Created TensorFlow device (/job:localhost/replica:0/task:0/device:GPU:0 with 0 MB memory) -> physical PluggableDevice (device: 0, name: METAL, pci bus id: <undefined>)\n"
     ]
    },
    {
     "name": "stdout",
     "output_type": "stream",
     "text": [
      "Metal device set to: Apple M1\n",
      "\n",
      "systemMemory: 8.00 GB\n",
      "maxCacheSize: 2.67 GB\n",
      "\n"
     ]
    }
   ],
   "source": [
    "model = tf.keras.Sequential([\n",
    "    tf.keras.layers.Conv2D(32, (3,3), activation='relu', input_shape=(256, 256, 3)),\n",
    "    tf.keras.layers.MaxPooling2D(2, 2),\n",
    "    tf.keras.layers.Conv2D(64, (3,3), activation='relu'),\n",
    "    tf.keras.layers.MaxPooling2D(2,2),\n",
    "    tf.keras.layers.Conv2D(128, (3,3), activation='relu'),\n",
    "    tf.keras.layers.MaxPooling2D(2,2),\n",
    "    tf.keras.layers.Flatten(),\n",
    "    tf.keras.layers.Dense(128, activation='relu'),\n",
    "    tf.keras.layers.Dropout(0.5),\n",
    "    tf.keras.layers.Dense(3, activation='softmax')\n",
    "])"
   ]
  },
  {
   "cell_type": "code",
   "execution_count": 26,
   "metadata": {},
   "outputs": [],
   "source": [
    "model.compile(optimizer='adam', loss = 'categorical_crossentropy', metrics = ['accuracy'])\n"
   ]
  },
  {
   "cell_type": "code",
   "execution_count": 30,
   "metadata": {},
   "outputs": [
    {
     "name": "stdout",
     "output_type": "stream",
     "text": [
      "Epoch 1/10\n"
     ]
    },
    {
     "ename": "InvalidArgumentError",
     "evalue": "Graph execution error:\n\nDetected at node 'categorical_crossentropy/softmax_cross_entropy_with_logits' defined at (most recent call last):\n    File \"/Users/vishals/miniconda3/envs/tensorflow_env/lib/python3.10/runpy.py\", line 196, in _run_module_as_main\n      return _run_code(code, main_globals, None,\n    File \"/Users/vishals/miniconda3/envs/tensorflow_env/lib/python3.10/runpy.py\", line 86, in _run_code\n      exec(code, run_globals)\n    File \"/Users/vishals/miniconda3/envs/tensorflow_env/lib/python3.10/site-packages/ipykernel_launcher.py\", line 17, in <module>\n      app.launch_new_instance()\n    File \"/Users/vishals/miniconda3/envs/tensorflow_env/lib/python3.10/site-packages/traitlets/config/application.py\", line 1043, in launch_instance\n      app.start()\n    File \"/Users/vishals/miniconda3/envs/tensorflow_env/lib/python3.10/site-packages/ipykernel/kernelapp.py\", line 725, in start\n      self.io_loop.start()\n    File \"/Users/vishals/miniconda3/envs/tensorflow_env/lib/python3.10/site-packages/tornado/platform/asyncio.py\", line 215, in start\n      self.asyncio_loop.run_forever()\n    File \"/Users/vishals/miniconda3/envs/tensorflow_env/lib/python3.10/asyncio/base_events.py\", line 603, in run_forever\n      self._run_once()\n    File \"/Users/vishals/miniconda3/envs/tensorflow_env/lib/python3.10/asyncio/base_events.py\", line 1906, in _run_once\n      handle._run()\n    File \"/Users/vishals/miniconda3/envs/tensorflow_env/lib/python3.10/asyncio/events.py\", line 80, in _run\n      self._context.run(self._callback, *self._args)\n    File \"/Users/vishals/miniconda3/envs/tensorflow_env/lib/python3.10/site-packages/ipykernel/kernelbase.py\", line 513, in dispatch_queue\n      await self.process_one()\n    File \"/Users/vishals/miniconda3/envs/tensorflow_env/lib/python3.10/site-packages/ipykernel/kernelbase.py\", line 502, in process_one\n      await dispatch(*args)\n    File \"/Users/vishals/miniconda3/envs/tensorflow_env/lib/python3.10/site-packages/ipykernel/kernelbase.py\", line 409, in dispatch_shell\n      await result\n    File \"/Users/vishals/miniconda3/envs/tensorflow_env/lib/python3.10/site-packages/ipykernel/kernelbase.py\", line 729, in execute_request\n      reply_content = await reply_content\n    File \"/Users/vishals/miniconda3/envs/tensorflow_env/lib/python3.10/site-packages/ipykernel/ipkernel.py\", line 422, in do_execute\n      res = shell.run_cell(\n    File \"/Users/vishals/miniconda3/envs/tensorflow_env/lib/python3.10/site-packages/ipykernel/zmqshell.py\", line 540, in run_cell\n      return super().run_cell(*args, **kwargs)\n    File \"/Users/vishals/miniconda3/envs/tensorflow_env/lib/python3.10/site-packages/IPython/core/interactiveshell.py\", line 2961, in run_cell\n      result = self._run_cell(\n    File \"/Users/vishals/miniconda3/envs/tensorflow_env/lib/python3.10/site-packages/IPython/core/interactiveshell.py\", line 3016, in _run_cell\n      result = runner(coro)\n    File \"/Users/vishals/miniconda3/envs/tensorflow_env/lib/python3.10/site-packages/IPython/core/async_helpers.py\", line 129, in _pseudo_sync_runner\n      coro.send(None)\n    File \"/Users/vishals/miniconda3/envs/tensorflow_env/lib/python3.10/site-packages/IPython/core/interactiveshell.py\", line 3221, in run_cell_async\n      has_raised = await self.run_ast_nodes(code_ast.body, cell_name,\n    File \"/Users/vishals/miniconda3/envs/tensorflow_env/lib/python3.10/site-packages/IPython/core/interactiveshell.py\", line 3400, in run_ast_nodes\n      if await self.run_code(code, result, async_=asy):\n    File \"/Users/vishals/miniconda3/envs/tensorflow_env/lib/python3.10/site-packages/IPython/core/interactiveshell.py\", line 3460, in run_code\n      exec(code_obj, self.user_global_ns, self.user_ns)\n    File \"/var/folders/gd/kcf7yq1s0tj51bt7fy6p0v780000gn/T/ipykernel_88242/2412006217.py\", line 1, in <module>\n      history = model.fit(training_set, epochs = 50, steps_per_epoch = 16, verbose = 1, validation_data = validation_set, validation_steps= 16)\n    File \"/Users/vishals/miniconda3/envs/tensorflow_env/lib/python3.10/site-packages/keras/utils/traceback_utils.py\", line 64, in error_handler\n      return fn(*args, **kwargs)\n    File \"/Users/vishals/miniconda3/envs/tensorflow_env/lib/python3.10/site-packages/keras/engine/training.py\", line 1409, in fit\n      tmp_logs = self.train_function(iterator)\n    File \"/Users/vishals/miniconda3/envs/tensorflow_env/lib/python3.10/site-packages/keras/engine/training.py\", line 1051, in train_function\n      return step_function(self, iterator)\n    File \"/Users/vishals/miniconda3/envs/tensorflow_env/lib/python3.10/site-packages/keras/engine/training.py\", line 1040, in step_function\n      outputs = model.distribute_strategy.run(run_step, args=(data,))\n    File \"/Users/vishals/miniconda3/envs/tensorflow_env/lib/python3.10/site-packages/keras/engine/training.py\", line 1030, in run_step\n      outputs = model.train_step(data)\n    File \"/Users/vishals/miniconda3/envs/tensorflow_env/lib/python3.10/site-packages/keras/engine/training.py\", line 890, in train_step\n      loss = self.compute_loss(x, y, y_pred, sample_weight)\n    File \"/Users/vishals/miniconda3/envs/tensorflow_env/lib/python3.10/site-packages/keras/engine/training.py\", line 948, in compute_loss\n      return self.compiled_loss(\n    File \"/Users/vishals/miniconda3/envs/tensorflow_env/lib/python3.10/site-packages/keras/engine/compile_utils.py\", line 201, in __call__\n      loss_value = loss_obj(y_t, y_p, sample_weight=sw)\n    File \"/Users/vishals/miniconda3/envs/tensorflow_env/lib/python3.10/site-packages/keras/losses.py\", line 139, in __call__\n      losses = call_fn(y_true, y_pred)\n    File \"/Users/vishals/miniconda3/envs/tensorflow_env/lib/python3.10/site-packages/keras/losses.py\", line 243, in call\n      return ag_fn(y_true, y_pred, **self._fn_kwargs)\n    File \"/Users/vishals/miniconda3/envs/tensorflow_env/lib/python3.10/site-packages/keras/losses.py\", line 1787, in categorical_crossentropy\n      return backend.categorical_crossentropy(\n    File \"/Users/vishals/miniconda3/envs/tensorflow_env/lib/python3.10/site-packages/keras/backend.py\", line 5134, in categorical_crossentropy\n      return tf.nn.softmax_cross_entropy_with_logits(\nNode: 'categorical_crossentropy/softmax_cross_entropy_with_logits'\nDetected at node 'categorical_crossentropy/softmax_cross_entropy_with_logits' defined at (most recent call last):\n    File \"/Users/vishals/miniconda3/envs/tensorflow_env/lib/python3.10/runpy.py\", line 196, in _run_module_as_main\n      return _run_code(code, main_globals, None,\n    File \"/Users/vishals/miniconda3/envs/tensorflow_env/lib/python3.10/runpy.py\", line 86, in _run_code\n      exec(code, run_globals)\n    File \"/Users/vishals/miniconda3/envs/tensorflow_env/lib/python3.10/site-packages/ipykernel_launcher.py\", line 17, in <module>\n      app.launch_new_instance()\n    File \"/Users/vishals/miniconda3/envs/tensorflow_env/lib/python3.10/site-packages/traitlets/config/application.py\", line 1043, in launch_instance\n      app.start()\n    File \"/Users/vishals/miniconda3/envs/tensorflow_env/lib/python3.10/site-packages/ipykernel/kernelapp.py\", line 725, in start\n      self.io_loop.start()\n    File \"/Users/vishals/miniconda3/envs/tensorflow_env/lib/python3.10/site-packages/tornado/platform/asyncio.py\", line 215, in start\n      self.asyncio_loop.run_forever()\n    File \"/Users/vishals/miniconda3/envs/tensorflow_env/lib/python3.10/asyncio/base_events.py\", line 603, in run_forever\n      self._run_once()\n    File \"/Users/vishals/miniconda3/envs/tensorflow_env/lib/python3.10/asyncio/base_events.py\", line 1906, in _run_once\n      handle._run()\n    File \"/Users/vishals/miniconda3/envs/tensorflow_env/lib/python3.10/asyncio/events.py\", line 80, in _run\n      self._context.run(self._callback, *self._args)\n    File \"/Users/vishals/miniconda3/envs/tensorflow_env/lib/python3.10/site-packages/ipykernel/kernelbase.py\", line 513, in dispatch_queue\n      await self.process_one()\n    File \"/Users/vishals/miniconda3/envs/tensorflow_env/lib/python3.10/site-packages/ipykernel/kernelbase.py\", line 502, in process_one\n      await dispatch(*args)\n    File \"/Users/vishals/miniconda3/envs/tensorflow_env/lib/python3.10/site-packages/ipykernel/kernelbase.py\", line 409, in dispatch_shell\n      await result\n    File \"/Users/vishals/miniconda3/envs/tensorflow_env/lib/python3.10/site-packages/ipykernel/kernelbase.py\", line 729, in execute_request\n      reply_content = await reply_content\n    File \"/Users/vishals/miniconda3/envs/tensorflow_env/lib/python3.10/site-packages/ipykernel/ipkernel.py\", line 422, in do_execute\n      res = shell.run_cell(\n    File \"/Users/vishals/miniconda3/envs/tensorflow_env/lib/python3.10/site-packages/ipykernel/zmqshell.py\", line 540, in run_cell\n      return super().run_cell(*args, **kwargs)\n    File \"/Users/vishals/miniconda3/envs/tensorflow_env/lib/python3.10/site-packages/IPython/core/interactiveshell.py\", line 2961, in run_cell\n      result = self._run_cell(\n    File \"/Users/vishals/miniconda3/envs/tensorflow_env/lib/python3.10/site-packages/IPython/core/interactiveshell.py\", line 3016, in _run_cell\n      result = runner(coro)\n    File \"/Users/vishals/miniconda3/envs/tensorflow_env/lib/python3.10/site-packages/IPython/core/async_helpers.py\", line 129, in _pseudo_sync_runner\n      coro.send(None)\n    File \"/Users/vishals/miniconda3/envs/tensorflow_env/lib/python3.10/site-packages/IPython/core/interactiveshell.py\", line 3221, in run_cell_async\n      has_raised = await self.run_ast_nodes(code_ast.body, cell_name,\n    File \"/Users/vishals/miniconda3/envs/tensorflow_env/lib/python3.10/site-packages/IPython/core/interactiveshell.py\", line 3400, in run_ast_nodes\n      if await self.run_code(code, result, async_=asy):\n    File \"/Users/vishals/miniconda3/envs/tensorflow_env/lib/python3.10/site-packages/IPython/core/interactiveshell.py\", line 3460, in run_code\n      exec(code_obj, self.user_global_ns, self.user_ns)\n    File \"/var/folders/gd/kcf7yq1s0tj51bt7fy6p0v780000gn/T/ipykernel_88242/2412006217.py\", line 1, in <module>\n      history = model.fit(training_set, epochs = 50, steps_per_epoch = 16, verbose = 1, validation_data = validation_set, validation_steps= 16)\n    File \"/Users/vishals/miniconda3/envs/tensorflow_env/lib/python3.10/site-packages/keras/utils/traceback_utils.py\", line 64, in error_handler\n      return fn(*args, **kwargs)\n    File \"/Users/vishals/miniconda3/envs/tensorflow_env/lib/python3.10/site-packages/keras/engine/training.py\", line 1409, in fit\n      tmp_logs = self.train_function(iterator)\n    File \"/Users/vishals/miniconda3/envs/tensorflow_env/lib/python3.10/site-packages/keras/engine/training.py\", line 1051, in train_function\n      return step_function(self, iterator)\n    File \"/Users/vishals/miniconda3/envs/tensorflow_env/lib/python3.10/site-packages/keras/engine/training.py\", line 1040, in step_function\n      outputs = model.distribute_strategy.run(run_step, args=(data,))\n    File \"/Users/vishals/miniconda3/envs/tensorflow_env/lib/python3.10/site-packages/keras/engine/training.py\", line 1030, in run_step\n      outputs = model.train_step(data)\n    File \"/Users/vishals/miniconda3/envs/tensorflow_env/lib/python3.10/site-packages/keras/engine/training.py\", line 890, in train_step\n      loss = self.compute_loss(x, y, y_pred, sample_weight)\n    File \"/Users/vishals/miniconda3/envs/tensorflow_env/lib/python3.10/site-packages/keras/engine/training.py\", line 948, in compute_loss\n      return self.compiled_loss(\n    File \"/Users/vishals/miniconda3/envs/tensorflow_env/lib/python3.10/site-packages/keras/engine/compile_utils.py\", line 201, in __call__\n      loss_value = loss_obj(y_t, y_p, sample_weight=sw)\n    File \"/Users/vishals/miniconda3/envs/tensorflow_env/lib/python3.10/site-packages/keras/losses.py\", line 139, in __call__\n      losses = call_fn(y_true, y_pred)\n    File \"/Users/vishals/miniconda3/envs/tensorflow_env/lib/python3.10/site-packages/keras/losses.py\", line 243, in call\n      return ag_fn(y_true, y_pred, **self._fn_kwargs)\n    File \"/Users/vishals/miniconda3/envs/tensorflow_env/lib/python3.10/site-packages/keras/losses.py\", line 1787, in categorical_crossentropy\n      return backend.categorical_crossentropy(\n    File \"/Users/vishals/miniconda3/envs/tensorflow_env/lib/python3.10/site-packages/keras/backend.py\", line 5134, in categorical_crossentropy\n      return tf.nn.softmax_cross_entropy_with_logits(\nNode: 'categorical_crossentropy/softmax_cross_entropy_with_logits'\n2 root error(s) found.\n  (0) INVALID_ARGUMENT:  logits and labels must be broadcastable: logits_size=[32,3] labels_size=[32,38]\n\t [[{{node categorical_crossentropy/softmax_cross_entropy_with_logits}}]]\n\t [[sequential/dense_1/Softmax/_20]]\n  (1) INVALID_ARGUMENT:  logits and labels must be broadcastable: logits_size=[32,3] labels_size=[32,38]\n\t [[{{node categorical_crossentropy/softmax_cross_entropy_with_logits}}]]\n0 successful operations.\n0 derived errors ignored. [Op:__inference_train_function_938]",
     "output_type": "error",
     "traceback": [
      "\u001b[0;31m---------------------------------------------------------------------------\u001b[0m",
      "\u001b[0;31mInvalidArgumentError\u001b[0m                      Traceback (most recent call last)",
      "Cell \u001b[0;32mIn[30], line 2\u001b[0m\n\u001b[1;32m      1\u001b[0m \u001b[39m# history = model.fit(training_set, epochs = 50, steps_per_epoch = 16, verbose = 1, validation_data = validation_set, validation_steps= 16)\u001b[39;00m\n\u001b[0;32m----> 2\u001b[0m history \u001b[39m=\u001b[39m model\u001b[39m.\u001b[39;49mfit(training_set, epochs\u001b[39m=\u001b[39;49m\u001b[39m10\u001b[39;49m, steps_per_epoch \u001b[39m=\u001b[39;49m \u001b[39m16\u001b[39;49m,  validation_data\u001b[39m=\u001b[39;49mvalidation_set)\n",
      "File \u001b[0;32m~/miniconda3/envs/tensorflow_env/lib/python3.10/site-packages/keras/utils/traceback_utils.py:67\u001b[0m, in \u001b[0;36mfilter_traceback.<locals>.error_handler\u001b[0;34m(*args, **kwargs)\u001b[0m\n\u001b[1;32m     65\u001b[0m \u001b[39mexcept\u001b[39;00m \u001b[39mException\u001b[39;00m \u001b[39mas\u001b[39;00m e:  \u001b[39m# pylint: disable=broad-except\u001b[39;00m\n\u001b[1;32m     66\u001b[0m   filtered_tb \u001b[39m=\u001b[39m _process_traceback_frames(e\u001b[39m.\u001b[39m__traceback__)\n\u001b[0;32m---> 67\u001b[0m   \u001b[39mraise\u001b[39;00m e\u001b[39m.\u001b[39mwith_traceback(filtered_tb) \u001b[39mfrom\u001b[39;00m \u001b[39mNone\u001b[39m\n\u001b[1;32m     68\u001b[0m \u001b[39mfinally\u001b[39;00m:\n\u001b[1;32m     69\u001b[0m   \u001b[39mdel\u001b[39;00m filtered_tb\n",
      "File \u001b[0;32m~/miniconda3/envs/tensorflow_env/lib/python3.10/site-packages/tensorflow/python/eager/execute.py:54\u001b[0m, in \u001b[0;36mquick_execute\u001b[0;34m(op_name, num_outputs, inputs, attrs, ctx, name)\u001b[0m\n\u001b[1;32m     52\u001b[0m \u001b[39mtry\u001b[39;00m:\n\u001b[1;32m     53\u001b[0m   ctx\u001b[39m.\u001b[39mensure_initialized()\n\u001b[0;32m---> 54\u001b[0m   tensors \u001b[39m=\u001b[39m pywrap_tfe\u001b[39m.\u001b[39mTFE_Py_Execute(ctx\u001b[39m.\u001b[39m_handle, device_name, op_name,\n\u001b[1;32m     55\u001b[0m                                       inputs, attrs, num_outputs)\n\u001b[1;32m     56\u001b[0m \u001b[39mexcept\u001b[39;00m core\u001b[39m.\u001b[39m_NotOkStatusException \u001b[39mas\u001b[39;00m e:\n\u001b[1;32m     57\u001b[0m   \u001b[39mif\u001b[39;00m name \u001b[39mis\u001b[39;00m \u001b[39mnot\u001b[39;00m \u001b[39mNone\u001b[39;00m:\n",
      "\u001b[0;31mInvalidArgumentError\u001b[0m: Graph execution error:\n\nDetected at node 'categorical_crossentropy/softmax_cross_entropy_with_logits' defined at (most recent call last):\n    File \"/Users/vishals/miniconda3/envs/tensorflow_env/lib/python3.10/runpy.py\", line 196, in _run_module_as_main\n      return _run_code(code, main_globals, None,\n    File \"/Users/vishals/miniconda3/envs/tensorflow_env/lib/python3.10/runpy.py\", line 86, in _run_code\n      exec(code, run_globals)\n    File \"/Users/vishals/miniconda3/envs/tensorflow_env/lib/python3.10/site-packages/ipykernel_launcher.py\", line 17, in <module>\n      app.launch_new_instance()\n    File \"/Users/vishals/miniconda3/envs/tensorflow_env/lib/python3.10/site-packages/traitlets/config/application.py\", line 1043, in launch_instance\n      app.start()\n    File \"/Users/vishals/miniconda3/envs/tensorflow_env/lib/python3.10/site-packages/ipykernel/kernelapp.py\", line 725, in start\n      self.io_loop.start()\n    File \"/Users/vishals/miniconda3/envs/tensorflow_env/lib/python3.10/site-packages/tornado/platform/asyncio.py\", line 215, in start\n      self.asyncio_loop.run_forever()\n    File \"/Users/vishals/miniconda3/envs/tensorflow_env/lib/python3.10/asyncio/base_events.py\", line 603, in run_forever\n      self._run_once()\n    File \"/Users/vishals/miniconda3/envs/tensorflow_env/lib/python3.10/asyncio/base_events.py\", line 1906, in _run_once\n      handle._run()\n    File \"/Users/vishals/miniconda3/envs/tensorflow_env/lib/python3.10/asyncio/events.py\", line 80, in _run\n      self._context.run(self._callback, *self._args)\n    File \"/Users/vishals/miniconda3/envs/tensorflow_env/lib/python3.10/site-packages/ipykernel/kernelbase.py\", line 513, in dispatch_queue\n      await self.process_one()\n    File \"/Users/vishals/miniconda3/envs/tensorflow_env/lib/python3.10/site-packages/ipykernel/kernelbase.py\", line 502, in process_one\n      await dispatch(*args)\n    File \"/Users/vishals/miniconda3/envs/tensorflow_env/lib/python3.10/site-packages/ipykernel/kernelbase.py\", line 409, in dispatch_shell\n      await result\n    File \"/Users/vishals/miniconda3/envs/tensorflow_env/lib/python3.10/site-packages/ipykernel/kernelbase.py\", line 729, in execute_request\n      reply_content = await reply_content\n    File \"/Users/vishals/miniconda3/envs/tensorflow_env/lib/python3.10/site-packages/ipykernel/ipkernel.py\", line 422, in do_execute\n      res = shell.run_cell(\n    File \"/Users/vishals/miniconda3/envs/tensorflow_env/lib/python3.10/site-packages/ipykernel/zmqshell.py\", line 540, in run_cell\n      return super().run_cell(*args, **kwargs)\n    File \"/Users/vishals/miniconda3/envs/tensorflow_env/lib/python3.10/site-packages/IPython/core/interactiveshell.py\", line 2961, in run_cell\n      result = self._run_cell(\n    File \"/Users/vishals/miniconda3/envs/tensorflow_env/lib/python3.10/site-packages/IPython/core/interactiveshell.py\", line 3016, in _run_cell\n      result = runner(coro)\n    File \"/Users/vishals/miniconda3/envs/tensorflow_env/lib/python3.10/site-packages/IPython/core/async_helpers.py\", line 129, in _pseudo_sync_runner\n      coro.send(None)\n    File \"/Users/vishals/miniconda3/envs/tensorflow_env/lib/python3.10/site-packages/IPython/core/interactiveshell.py\", line 3221, in run_cell_async\n      has_raised = await self.run_ast_nodes(code_ast.body, cell_name,\n    File \"/Users/vishals/miniconda3/envs/tensorflow_env/lib/python3.10/site-packages/IPython/core/interactiveshell.py\", line 3400, in run_ast_nodes\n      if await self.run_code(code, result, async_=asy):\n    File \"/Users/vishals/miniconda3/envs/tensorflow_env/lib/python3.10/site-packages/IPython/core/interactiveshell.py\", line 3460, in run_code\n      exec(code_obj, self.user_global_ns, self.user_ns)\n    File \"/var/folders/gd/kcf7yq1s0tj51bt7fy6p0v780000gn/T/ipykernel_88242/2412006217.py\", line 1, in <module>\n      history = model.fit(training_set, epochs = 50, steps_per_epoch = 16, verbose = 1, validation_data = validation_set, validation_steps= 16)\n    File \"/Users/vishals/miniconda3/envs/tensorflow_env/lib/python3.10/site-packages/keras/utils/traceback_utils.py\", line 64, in error_handler\n      return fn(*args, **kwargs)\n    File \"/Users/vishals/miniconda3/envs/tensorflow_env/lib/python3.10/site-packages/keras/engine/training.py\", line 1409, in fit\n      tmp_logs = self.train_function(iterator)\n    File \"/Users/vishals/miniconda3/envs/tensorflow_env/lib/python3.10/site-packages/keras/engine/training.py\", line 1051, in train_function\n      return step_function(self, iterator)\n    File \"/Users/vishals/miniconda3/envs/tensorflow_env/lib/python3.10/site-packages/keras/engine/training.py\", line 1040, in step_function\n      outputs = model.distribute_strategy.run(run_step, args=(data,))\n    File \"/Users/vishals/miniconda3/envs/tensorflow_env/lib/python3.10/site-packages/keras/engine/training.py\", line 1030, in run_step\n      outputs = model.train_step(data)\n    File \"/Users/vishals/miniconda3/envs/tensorflow_env/lib/python3.10/site-packages/keras/engine/training.py\", line 890, in train_step\n      loss = self.compute_loss(x, y, y_pred, sample_weight)\n    File \"/Users/vishals/miniconda3/envs/tensorflow_env/lib/python3.10/site-packages/keras/engine/training.py\", line 948, in compute_loss\n      return self.compiled_loss(\n    File \"/Users/vishals/miniconda3/envs/tensorflow_env/lib/python3.10/site-packages/keras/engine/compile_utils.py\", line 201, in __call__\n      loss_value = loss_obj(y_t, y_p, sample_weight=sw)\n    File \"/Users/vishals/miniconda3/envs/tensorflow_env/lib/python3.10/site-packages/keras/losses.py\", line 139, in __call__\n      losses = call_fn(y_true, y_pred)\n    File \"/Users/vishals/miniconda3/envs/tensorflow_env/lib/python3.10/site-packages/keras/losses.py\", line 243, in call\n      return ag_fn(y_true, y_pred, **self._fn_kwargs)\n    File \"/Users/vishals/miniconda3/envs/tensorflow_env/lib/python3.10/site-packages/keras/losses.py\", line 1787, in categorical_crossentropy\n      return backend.categorical_crossentropy(\n    File \"/Users/vishals/miniconda3/envs/tensorflow_env/lib/python3.10/site-packages/keras/backend.py\", line 5134, in categorical_crossentropy\n      return tf.nn.softmax_cross_entropy_with_logits(\nNode: 'categorical_crossentropy/softmax_cross_entropy_with_logits'\nDetected at node 'categorical_crossentropy/softmax_cross_entropy_with_logits' defined at (most recent call last):\n    File \"/Users/vishals/miniconda3/envs/tensorflow_env/lib/python3.10/runpy.py\", line 196, in _run_module_as_main\n      return _run_code(code, main_globals, None,\n    File \"/Users/vishals/miniconda3/envs/tensorflow_env/lib/python3.10/runpy.py\", line 86, in _run_code\n      exec(code, run_globals)\n    File \"/Users/vishals/miniconda3/envs/tensorflow_env/lib/python3.10/site-packages/ipykernel_launcher.py\", line 17, in <module>\n      app.launch_new_instance()\n    File \"/Users/vishals/miniconda3/envs/tensorflow_env/lib/python3.10/site-packages/traitlets/config/application.py\", line 1043, in launch_instance\n      app.start()\n    File \"/Users/vishals/miniconda3/envs/tensorflow_env/lib/python3.10/site-packages/ipykernel/kernelapp.py\", line 725, in start\n      self.io_loop.start()\n    File \"/Users/vishals/miniconda3/envs/tensorflow_env/lib/python3.10/site-packages/tornado/platform/asyncio.py\", line 215, in start\n      self.asyncio_loop.run_forever()\n    File \"/Users/vishals/miniconda3/envs/tensorflow_env/lib/python3.10/asyncio/base_events.py\", line 603, in run_forever\n      self._run_once()\n    File \"/Users/vishals/miniconda3/envs/tensorflow_env/lib/python3.10/asyncio/base_events.py\", line 1906, in _run_once\n      handle._run()\n    File \"/Users/vishals/miniconda3/envs/tensorflow_env/lib/python3.10/asyncio/events.py\", line 80, in _run\n      self._context.run(self._callback, *self._args)\n    File \"/Users/vishals/miniconda3/envs/tensorflow_env/lib/python3.10/site-packages/ipykernel/kernelbase.py\", line 513, in dispatch_queue\n      await self.process_one()\n    File \"/Users/vishals/miniconda3/envs/tensorflow_env/lib/python3.10/site-packages/ipykernel/kernelbase.py\", line 502, in process_one\n      await dispatch(*args)\n    File \"/Users/vishals/miniconda3/envs/tensorflow_env/lib/python3.10/site-packages/ipykernel/kernelbase.py\", line 409, in dispatch_shell\n      await result\n    File \"/Users/vishals/miniconda3/envs/tensorflow_env/lib/python3.10/site-packages/ipykernel/kernelbase.py\", line 729, in execute_request\n      reply_content = await reply_content\n    File \"/Users/vishals/miniconda3/envs/tensorflow_env/lib/python3.10/site-packages/ipykernel/ipkernel.py\", line 422, in do_execute\n      res = shell.run_cell(\n    File \"/Users/vishals/miniconda3/envs/tensorflow_env/lib/python3.10/site-packages/ipykernel/zmqshell.py\", line 540, in run_cell\n      return super().run_cell(*args, **kwargs)\n    File \"/Users/vishals/miniconda3/envs/tensorflow_env/lib/python3.10/site-packages/IPython/core/interactiveshell.py\", line 2961, in run_cell\n      result = self._run_cell(\n    File \"/Users/vishals/miniconda3/envs/tensorflow_env/lib/python3.10/site-packages/IPython/core/interactiveshell.py\", line 3016, in _run_cell\n      result = runner(coro)\n    File \"/Users/vishals/miniconda3/envs/tensorflow_env/lib/python3.10/site-packages/IPython/core/async_helpers.py\", line 129, in _pseudo_sync_runner\n      coro.send(None)\n    File \"/Users/vishals/miniconda3/envs/tensorflow_env/lib/python3.10/site-packages/IPython/core/interactiveshell.py\", line 3221, in run_cell_async\n      has_raised = await self.run_ast_nodes(code_ast.body, cell_name,\n    File \"/Users/vishals/miniconda3/envs/tensorflow_env/lib/python3.10/site-packages/IPython/core/interactiveshell.py\", line 3400, in run_ast_nodes\n      if await self.run_code(code, result, async_=asy):\n    File \"/Users/vishals/miniconda3/envs/tensorflow_env/lib/python3.10/site-packages/IPython/core/interactiveshell.py\", line 3460, in run_code\n      exec(code_obj, self.user_global_ns, self.user_ns)\n    File \"/var/folders/gd/kcf7yq1s0tj51bt7fy6p0v780000gn/T/ipykernel_88242/2412006217.py\", line 1, in <module>\n      history = model.fit(training_set, epochs = 50, steps_per_epoch = 16, verbose = 1, validation_data = validation_set, validation_steps= 16)\n    File \"/Users/vishals/miniconda3/envs/tensorflow_env/lib/python3.10/site-packages/keras/utils/traceback_utils.py\", line 64, in error_handler\n      return fn(*args, **kwargs)\n    File \"/Users/vishals/miniconda3/envs/tensorflow_env/lib/python3.10/site-packages/keras/engine/training.py\", line 1409, in fit\n      tmp_logs = self.train_function(iterator)\n    File \"/Users/vishals/miniconda3/envs/tensorflow_env/lib/python3.10/site-packages/keras/engine/training.py\", line 1051, in train_function\n      return step_function(self, iterator)\n    File \"/Users/vishals/miniconda3/envs/tensorflow_env/lib/python3.10/site-packages/keras/engine/training.py\", line 1040, in step_function\n      outputs = model.distribute_strategy.run(run_step, args=(data,))\n    File \"/Users/vishals/miniconda3/envs/tensorflow_env/lib/python3.10/site-packages/keras/engine/training.py\", line 1030, in run_step\n      outputs = model.train_step(data)\n    File \"/Users/vishals/miniconda3/envs/tensorflow_env/lib/python3.10/site-packages/keras/engine/training.py\", line 890, in train_step\n      loss = self.compute_loss(x, y, y_pred, sample_weight)\n    File \"/Users/vishals/miniconda3/envs/tensorflow_env/lib/python3.10/site-packages/keras/engine/training.py\", line 948, in compute_loss\n      return self.compiled_loss(\n    File \"/Users/vishals/miniconda3/envs/tensorflow_env/lib/python3.10/site-packages/keras/engine/compile_utils.py\", line 201, in __call__\n      loss_value = loss_obj(y_t, y_p, sample_weight=sw)\n    File \"/Users/vishals/miniconda3/envs/tensorflow_env/lib/python3.10/site-packages/keras/losses.py\", line 139, in __call__\n      losses = call_fn(y_true, y_pred)\n    File \"/Users/vishals/miniconda3/envs/tensorflow_env/lib/python3.10/site-packages/keras/losses.py\", line 243, in call\n      return ag_fn(y_true, y_pred, **self._fn_kwargs)\n    File \"/Users/vishals/miniconda3/envs/tensorflow_env/lib/python3.10/site-packages/keras/losses.py\", line 1787, in categorical_crossentropy\n      return backend.categorical_crossentropy(\n    File \"/Users/vishals/miniconda3/envs/tensorflow_env/lib/python3.10/site-packages/keras/backend.py\", line 5134, in categorical_crossentropy\n      return tf.nn.softmax_cross_entropy_with_logits(\nNode: 'categorical_crossentropy/softmax_cross_entropy_with_logits'\n2 root error(s) found.\n  (0) INVALID_ARGUMENT:  logits and labels must be broadcastable: logits_size=[32,3] labels_size=[32,38]\n\t [[{{node categorical_crossentropy/softmax_cross_entropy_with_logits}}]]\n\t [[sequential/dense_1/Softmax/_20]]\n  (1) INVALID_ARGUMENT:  logits and labels must be broadcastable: logits_size=[32,3] labels_size=[32,38]\n\t [[{{node categorical_crossentropy/softmax_cross_entropy_with_logits}}]]\n0 successful operations.\n0 derived errors ignored. [Op:__inference_train_function_938]"
     ]
    }
   ],
   "source": [
    "history = model.fit(training_set, epochs = 50, steps_per_epoch = 16, verbose = 1, validation_data = validation_set, validation_steps= 16)\n"
   ]
  }
 ],
 "metadata": {
  "kernelspec": {
   "display_name": "tensorflow_env",
   "language": "python",
   "name": "python3"
  },
  "language_info": {
   "codemirror_mode": {
    "name": "ipython",
    "version": 3
   },
   "file_extension": ".py",
   "mimetype": "text/x-python",
   "name": "python",
   "nbconvert_exporter": "python",
   "pygments_lexer": "ipython3",
   "version": "3.10.9"
  },
  "orig_nbformat": 4,
  "vscode": {
   "interpreter": {
    "hash": "1a50bf01ff8107af639e2bc82e557f291c5b0ee863386a3edf7f8f4387e47f4c"
   }
  }
 },
 "nbformat": 4,
 "nbformat_minor": 2
}
